<mujoco>
  <compiler inertiafromgeom="true" angle="radian" coordinate="local"/>
  <option timestep="0.01" gravity="0 0 0" iterations="20" integrator="Euler"/>
  <default>
    <joint damping="1" limited='false'/>
    <geom friction=".5 .1 .1" density="1000" margin="0.002" condim="1" contype="2" conaffinity="1"/>
  </default>
  <asset>
    <texture type="2d" name="groundplane" builtin="checker" rgb1="0.2 0.3 0.4" rgb2="0.1 0.2 0.3" width="100" height="100"/>
    <texture name="skybox" type="skybox" builtin="gradient" rgb1=".4 .6 .8" rgb2="0 0 0" width="800" height="800" mark="random" markrgb="1 1 1"/>
    <material name="groundplane" texture="groundplane" texrepeat="20 20"/>
    <material name="target" rgba=".6 .3 .3 1"/>
  </asset>
  <visual>
    <headlight ambient=".4 .4 .4" diffuse=".8 .8 .8" specular="0.1 0.1 0.1"/>
    <map znear=".01"/>
    <quality shadowsize="2048"/>
  </visual>
  <worldbody>
    <camera name="global_view" pos="0 0 50" xyaxes="1 0 0 0 1 0" fovy="45"/>
    <camera name="global_view2" pos="0 -15 50" xyaxes="1 0 0 0 0.9659 0.2588" fovy="45"/>
    <geom name="ground" size="40 40 0.25" pos="0 0 -0.1" type="plane" contype="1" conaffinity="0" material="groundplane"/>
    <body name="particle_1" pos="0 0 0">
      <geom name="particle_geom_1" type="box" size="0.5 0.5 0.5" rgba="0.0 0.0 1.0 0.0" friction="0.0 0.1 0.1" mass="0.01" contype="1"/>
      <site name="particle_site_1" pos="0.0 0.0 0.0" type="box" size="0.5 0.5 0.5" rgba="0.3 0.6 0.3 1"/>
      <joint name="ball_x_1" type="slide" pos="0 0 0" axis="1 0 0"/>
      <joint name="ball_y_1" type="slide" pos="0 0 0" axis="0 1 0"/>
    </body>
    <body name="barrier_1" pos="0 0 0">
      <geom name="barrier_geom_1" type="box" size="0.5 1.5 0.5" rgba="0.5 0 0.5 1" friction="0.0 0.1 0.1" mass="0.01" contype="1"/>
      <site name="barrier_site_1" pos="0.0 0.0 0.0" type="box" size="0.5 1.5 0.5" rgba="0.5 0 0.5 1"/>
      <joint name="barrier_x_1" type="slide" pos="0 0 0" axis="1 0 0"/>
      <joint name="barrier_y_1" type="slide" pos="0 0 0" axis="0 1 0"/>
    </body>
    <body name="barrier_2" pos="0 1 0">
      <geom name="barrier_geom_2" type="box" size="1.5 0.5 0.5" rgba="0.5 0 0.5 1" friction="0.0 0.1 0.1" mass="0.01" contype="1"/>
      <site name="barrier_site_2" pos="0.0 0.0 0.0" type="box" size="1.5 0.5 0.5" rgba="0.5 0 0.5 1"/>
      <joint name="barrier_x_2" type="slide" pos="0 0 0" axis="1 0 0"/>
      <joint name="barrier_y_2" type="slide" pos="0 0 0" axis="0 1 0"/>
    </body>
  </worldbody>
  <actuator>
    <!-- These are just dummy actuators for providing ranges -->
    <motor name="motor_x_1" joint="ball_x_1" ctrlrange="-1.0 1.0" ctrllimited="true" gear= "100"/>
    <motor name="motor_y_1" joint="ball_y_1" ctrlrange="-1.0 1.0" ctrllimited="true" gear="100"/>
    <motor name="motor_x_3" joint="barrier_x_1" ctrlrange="-1.0 1.0" ctrllimited="true" gear= "100"/>
    <motor name="motor_y_3" joint="barrier_y_1" ctrlrange="-1.0 1.0" ctrllimited="true" gear="100"/>
    <motor name="motor_x_4" joint="barrier_x_2" ctrlrange="-1.0 1.0" ctrllimited="true" gear= "100"/>
    <motor name="motor_y_4" joint="barrier_y_2" ctrlrange="-1.0 1.0" ctrllimited="true" gear="100"/>
  </actuator>
</mujoco>
