<mujoco>
	<body mocap="true" name="robot1:mocap" pos="0 0 0">
		<geom conaffinity="0" contype="0" pos="0 0 0" rgba="0 0.5 0 0.7" size="0.005 0.005 0.005" type="box"></geom>
		<geom conaffinity="0" contype="0" pos="0 0 0" rgba="0 0.5 0 0.1" size="1 0.005 0.005" type="box"></geom>
		<geom conaffinity="0" contype="0" pos="0 0 0" rgba="0 0.5 0 0.1" size="0.005 1 0.001" type="box"></geom>
		<geom conaffinity="0" contype="0" pos="0 0 0" rgba="0 0.5 0 0.1" size="0.005 0.005 1" type="box"></geom>
	</body>
	<body childclass="robot1:fetch" name="robot1:base_link" pos="0.3869 1.1641 0.3">
		<joint armature="0.0001" axis="1 0 0" damping="1e+11" name="robot1:slide0" pos="0 0 0" type="slide"></joint>
		<joint armature="0.0001" axis="0 1 0" damping="1e+11" name="robot1:slide1" pos="0 0 0" type="slide"></joint>
		<joint armature="0.0001" axis="0 0 1" damping="1e+11" name="robot1:slide2" pos="0 0 0" type="slide"></joint>
		<inertial diaginertia="1.2869 1.2236 0.9868" mass="70.1294" pos="-0.0036 0 0.0014" quat="0.7605 -0.0133 -0.0061 0.6491"></inertial>
		<geom mesh="robot1:base_link" name="robot1:base_link" material="robot1:base_mat" class="robot1:none"></geom>
		<body name="robot1:torso_lift_link" pos="-0.0869 0 0.3774">
			<body name="robot1:shoulder_pan_link" pos="0.1195 0 0.2486">
				<inertial diaginertia="0.009 0.0086 0.0041" mass="2.5587" pos="0.0927 -0.0056 0.0564" quat="-0.1364 0.7624 -0.1562 0.613"></inertial>
				<joint axis="0 0 1" limited="true" name="robot1:shoulder_pan_joint" range="-1.6056 1.6056"></joint>
				<geom mesh="robot1:shoulder_pan_link" name="robot1:shoulder_pan_link" material="robot1:arm_mat" rgba="1.0 0.549 0.0 1"></geom>
				<body name="robot1:shoulder_lift_link" pos="0.117 0 0.06">
					<inertial diaginertia="0.0086 0.0084 0.002" mass="2.1299" pos="0.1279 0.0073 0" quat="0.4332 0.4332 0.5589 0.5589"></inertial>
					<joint axis="0 1 0" limited="true" name="robot1:elbow_flex_joint" range="-2.251 2.251"></joint>
					<geom mesh="robot1:elbow_flex_link" name="robot1:elbow_flex_link" material="robot1:arm_mat" class="robot1:brown"></geom>
					<body name="robot1:forearm_roll_link" pos="0.197 0 0">
						<inertial diaginertia="0.0035 0.0031 0.0015" mass="1.6563" pos="0.1097 -0.0266 0" quat="-0.0715 0.7035 0.0715 0.7035"></inertial>
						<joint armature="2.7538" axis="1 0 0" damping="3.5247" frictionloss="0" limited="false" name="robot1:forearm_roll_joint" stiffness="10"></joint>
						<geom mesh="robot1:forearm_roll_link" name="robot1:forearm_roll_link" material="robot1:arm_mat" rgba="1.0 0.549 0.0 1"></geom>
						<body name="robot1:wrist_flex_link" pos="0.1245 0 0">
							<inertial diaginertia="0.0042 0.0042 0.0018" mass="1.725" pos="0.0882 0.0009 -0.0001" quat="0.4895 0.4895 0.5103 0.5103"></inertial>
							<joint axis="0 1 0" limited="true" name="robot1:wrist_flex_joint" range="-2.16 2.16"></joint>
							<geom mesh="robot1:wrist_flex_link" name="robot1:wrist_flex_link" material="robot1:arm_mat" class="robot1:brown"></geom>
							<body name="robot1:wrist_roll_link" pos="0.1385 0 0">
								<inertial diaginertia="0.0001 0.0001 0.0001" mass="0.1354" pos="0.0095 0.0004 -0.0002"></inertial>
								<joint axis="1 0 0" limited="false" name="robot1:wrist_roll_joint"></joint>
								<geom mesh="robot1:wrist_roll_link" name="robot1:wrist_roll_link" material="robot1:arm_mat" rgba="1.0 0.549 0.0 1"></geom>
								<body euler="0 0 0" name="robot1:gripper_link" pos="0.1664 0 0">
									<inertial diaginertia="0.0024 0.0019 0.0013" mass="1.5175" pos="-0.09 -0.0001 -0.0017" quat="0 0.7071 0 0.7071"></inertial>
									<geom mesh="robot1:gripper_link" name="robot1:gripper_link" material="robot1:gripper_mat" rgba="1.0 0.549 0.0 1"></geom>

									<body childclass="robot1:fetchGripper" name="robot1:r_gripper_finger_link" pos="0 0.0159 0">
										<inertial diaginertia="0.1 0.1 0.1" mass="4" pos="-0.01 0 0"></inertial>
										<joint axis="0 1 0" name="robot1:r_gripper_finger_joint" range="0 0.05"></joint>
										<geom pos="0 -0.008 0" size="0.0385 0.007 0.0135" type="box" name="robot1:r_gripper_finger_link" material="robot1:gripper_finger_mat" condim="4" friction="1 0.05 0.01" rgba="1 0 0 0"></geom>
									</body>
									<body childclass="robot1:fetchGripper" name="robot1:l_gripper_finger_link" pos="0 -0.0159 0">
										<inertial diaginertia="0.1 0.1 0.1" mass="4" pos="-0.01 0 0"></inertial>
										<joint axis="0 -1 0" name="robot1:l_gripper_finger_joint" range="0 0.05"></joint>
										<geom pos="0 0.008 0" size="0.0385 0.007 0.0135" type="box" name="robot1:l_gripper_finger_link" material="robot1:gripper_finger_mat" condim="4" friction="1 0.05 0.01" ></geom>
									</body>
									<site name="robot1:grip" pos="0.02 0 0" rgba="0 0 0 0" size="0.02 0.02 0.02"></site>
								</body>
							</body>
						</body>
					</body>
				</body>
			</body>
		</body>
		<body name="robot1:estop_link" pos="-0.1246 0.2389 0.3113" quat="0.7071 0.7071 0 0">
			<inertial diaginertia="0 0 0" mass="0.002" pos="0.0024 -0.0033 0.0067" quat="0.3774 -0.1814 0.1375 0.8977"></inertial>
			<geom mesh="robot1:estop_link" rgba="0.0 0 0 0" name="robot1:estop_link"></geom>
		</body>
		<body name="robot1:laser_link" pos="0.235 0 0.2878" quat="0 1 0 0">
			<inertial diaginertia="0 0 0" mass="0.0083" pos="-0.0306 0.0007 0.0552" quat="0.5878 0.5378 -0.4578 0.3945"></inertial>
			<geom mesh="robot1:laser_link" rgba="0 0 0 0" name="robot1:laser_link"></geom>
			<camera euler="1.55 -1.55 3.14" fovy="25" name="lidar2" pos="0 0 0.02"></camera>
		</body>
		<!--
		<body name="robot1:torso_fixed_link" pos="-0.0869 0 0.2774">
			<inertial diaginertia="0.3865 0.3394 0.1009" mass="13.2775" pos="-0.0722 0.0057 0.2656" quat="0.9995 0.0249 0.0177 0.011"></inertial>
			<geom mesh="robot1:torso_fixed_link" name="robot1:torso_fixed_link" class="robot1:brown"></geom>
		</body>
		-->
		<body name="robot1:torso_fixed_link" pos="-0.0869 0 0.5">
			<inertial diaginertia="0.3865 0.3394 0.1009" mass="13.2775" pos="-0.0722 0.0057 0.2656" quat="0.9995 0.0249 0.0177 0.011"></inertial>
			<geom type="cylinder" size="0.12 0.25" name="robot1:torso_fixed_link" class="robot1:brown"></geom>
			<!-- 底部圆柱体 -->
			<geom type="cylinder" size="0.3 0.01" pos="0 0 -0.5" rgba="0 0 0.05 1" name="cys0"/>
    
			<geom type="cylinder" size="0.29 0.01" pos="0 0 -0.49" rgba="1.0 0.549 0.0 1" name="cys1"/>
			
			<geom type="cylinder" size="0.28 0.01" pos="0 0 -0.48" rgba="1.0 0.549 0.0 1" name="cys2"/>
			
			<geom type="cylinder" size="0.27 0.01" pos="0 0 -0.47" rgba="1.0 0.549 0.0 1" name="cys3"/>
			
			<geom type="cylinder" size="0.26 0.01" pos="0 0 -0.46" rgba="1.0 0.549 0.0 1" name="cys4"/>
			
			<geom type="cylinder" size="0.25 0.01" pos="0 0 -0.45" rgba="1.0 0.549 0.0 1" name="cys5"/>
			
			<geom type="cylinder" size="0.24 0.01" pos="0 0 -0.44" rgba="1.0 0.549 0.0 1" name="cys6"/>
			
			<geom type="cylinder" size="0.23 0.01" pos="0 0 -0.43" rgba="1.0 0.549 0.0 1" name="cys7"/>
			
			<geom type="cylinder" size="0.22 0.01" pos="0 0 -0.42" rgba="1.0 0.549 0.0 1" name="cys8"/>
			
			<geom type="cylinder" size="0.21 0.01" pos="0 0 -0.41" rgba="1.0 0.549 0.0 1" name="cys9"/>
			
			<geom type="cylinder" size="0.20 0.01" pos="0 0 -0.4" rgba="1.0 0.549 0.0 1" name="cys10"/>
			
			<geom type="cylinder" size="0.19 0.01" pos="0 0 -0.39" rgba="1.0 0.549 0.0 1" name="cys11"/>
			
			<geom type="cylinder" size="0.18 0.01" pos="0 0 -0.38" rgba="1.0 0.549 0.0 1" name="cys12"/>
			
			<geom type="cylinder" size="0.17 0.01" pos="0 0 -0.37" rgba="1.0 0.549 0.0 1" name="cys13"/>
			
			<geom type="cylinder" size="0.16 0.01" pos="0 0 -0.36" rgba="1.0 0.549 0.0 1" name="cys14"/>

			<geom type="cylinder" size="0.15 0.20" pos="0 0 -0.35" rgba="1.0 0.549 0.0 1" name="cys15"/>

			<geom type="cylinder" size="0.15 0.02" pos="0 0 -0.15" rgba="0.0 0.0 0.0 1" name="cys16"/>

			<geom type="cylinder" size="0.15 0.10" pos="0 0 -0.02" rgba="1.0 0.549 0.0 1" name="cys17"/>

			<geom type="cylinder" size="0.145 0.01" pos="0 0 -0.01" rgba="1.0 0.549 0.0 1" name="cys18"/>

			<geom type="cylinder" size="0.14 0.01" pos="0 0 0.00" rgba="1.0 0.549 0.0 1" name="cys19"/>

			<geom type="cylinder" size="0.135 0.01" pos="0 0 0.01" rgba="1.0 0.549 0.0 1" name="cys20"/>

			<geom type="cylinder" size="0.13 0.01" pos="0 0 0.02" rgba="1.0 0.549 0.0 1" name="cys21"/>

			<geom type="cylinder" size="0.125 0.01" pos="0 0 0.03" rgba="1.0 0.549 0.0 1" name="cys22"/>
					<!-- 锥体 -->
			
		</body>
		<!--
		<geom type="capsule" size="0.15 0.1" pos="-0.0869 0 0.1" rgba="1.0 0.549 0.0 1" name="taper"/>
		<body name="robot1:torso_fixed_link2" pos="-0.0869 0 -0.2774">
			<inertial diaginertia="0.3865 0.3394 0.1009" mass="13.2775" pos="-0.0722 0.0057 0.2656" quat="0.9995 0.0249 0.0177 0.011"></inertial>
			<geom type="cylinder" size="0.1 0.5" name="robot1:torso_fixed_link2" class="robot1:blue"></geom>
		</body>
		-->
		<body name="robot1:external_camera_body_0" pos="0 0 0">
			<camera euler="0 0.75 1.57" fovy="43.3" name="external_camera_1" pos="1.3 0 1.2"></camera>
		</body>
	</body>
</mujoco>
